Workbook

Sheet Cover
A1: Information Security Risk Register
A2: Lantern Managed Services Ltd
A4: Prepared by | B4: Eugene Hayford
A5: Document reference | B5: LMS-ISMS-RR-001
A6: Version | B6: 1.1
A7: Date | B7: October 2026
A8: Classification | B8: Confidential, Lantern internal
A9: Standard | B9: ISO/IEC 27001:2022 Clauses 6.1.2, 6.1.3, 8.2 and 8.3; guidance from ISO/IEC 27005:2022
A10: Related documents | B10: Scenario Dossier: Lantern Managed Services Ltd; ISO/IEC 27001:2022 Gap Assessment (findings GAP-001 to GAP-040); Statement of Applicability LMS-ISMS-SOA-001; Third-Party Risk Assessment TPRA-001
A11: Approval status | B11: Draft for approval by the Managing Director as risk appetite owner
A13: Scenario notice
A14: Lantern Managed Services Ltd is a fictional organisation used to demonstrate risk management methodology. No real client, employee or commercial information is used. The register is the output of the risk assessment recommended in finding GAP-002 of the accompanying gap assessment.
A16: How to use this workbook
A17: Methodology | B17: Scoring scales, rating bands, risk appetite by category, treatment options and review frequency. Change the appetite thresholds here and the register updates.
A18: Risk Register | B18: The 21 identified risks. Each risk is written as cause, event and consequence, scored on current controls, and traced to Annex A controls and gap findings.
A19: Treatment Plan | B19: The 43 actions that deliver the treatment for each risk, with owner, phase, target date and the evidence that will prove completion.
A20: Summary | B20: Heat maps of current and target risk, counts by rating, the highest current risks and the risks that remain above appetite.
A21: Change Log | B21: Version history of the register.
A22: Editing | B22: Blue cells on the Risk Register (likelihood, impact, treatment option, status, review date) are inputs. Score, rating, appetite threshold, appetite check and next review date are formulas and should not be overwritten.

Sheet Summary
A1: Risk Summary
A2: All figures calculate from the Risk Register
A4: Current risk (existing controls) | H4: Target risk (after treatment)
A5: Likelihood / Impact | B5: 1 | C5: 2 | D5: 3 | E5: 4 | F5: 5 | H5: Likelihood / Impact | I5: 1 | J5: 2 | K5: 3 | L5: 4 | M5: 5
A6: 5 | B6: =COUNTIFS('Risk Register'!$K$2:$K$22,5,'Risk Register'!$L$2:$L$22,1) -> 0 | C6: =COUNTIFS('Risk Register'!$K$2:$K$22,5,'Risk Register'!$L$2:$L$22,2) -> 0 | D6: =COUNTIFS('Risk Register'!$K$2:$K$22,5,'Risk Register'!$L$2:$L$22,3) -> 0 | E6: =COUNTIFS('Risk Register'!$K$2:$K$22,5,'Risk Register'!$L$2:$L$22,4) -> 1 | F6: =COUNTIFS('Risk Register'!$K$2:$K$22,5,'Risk Register'!$L$2:$L$22,5) -> 0 | H6: 5 | I6: =COUNTIFS('Risk Register'!$T$2:$T$22,5,'Risk Register'!$U$2:$U$22,1) -> 0 | J6: =COUNTIFS('Risk Register'!$T$2:$T$22,5,'Risk Register'!$U$2:$U$22,2) -> 0 | K6: =COUNTIFS('Risk Register'!$T$2:$T$22,5,'Risk Register'!$U$2:$U$22,3) -> 0 | L6: =COUNTIFS('Risk Register'!$T$2:$T$22,5,'Risk Register'!$U$2:$U$22,4) -> 0 | M6: =COUNTIFS('Risk Register'!$T$2:$T$22,5,'Risk Register'!$U$2:$U$22,5) -> 0
A7: 4 | B7: =COUNTIFS('Risk Register'!$K$2:$K$22,4,'Risk Register'!$L$2:$L$22,1) -> 0 | C7: =COUNTIFS('Risk Register'!$K$2:$K$22,4,'Risk Register'!$L$2:$L$22,2) -> 0 | D7: =COUNTIFS('Risk Register'!$K$2:$K$22,4,'Risk Register'!$L$2:$L$22,3) -> 1 | E7: =COUNTIFS('Risk Register'!$K$2:$K$22,4,'Risk Register'!$L$2:$L$22,4) -> 4 | F7: =COUNTIFS('Risk Register'!$K$2:$K$22,4,'Risk Register'!$L$2:$L$22,5) -> 1 | H7: 4 | I7: =COUNTIFS('Risk Register'!$T$2:$T$22,4,'Risk Register'!$U$2:$U$22,1) -> 0 | J7: =COUNTIFS('Risk Register'!$T$2:$T$22,4,'Risk Register'!$U$2:$U$22,2) -> 0 | K7: =COUNTIFS('Risk Register'!$T$2:$T$22,4,'Risk Register'!$U$2:$U$22,3) -> 0 | L7: =COUNTIFS('Risk Register'!$T$2:$T$22,4,'Risk Register'!$U$2:$U$22,4) -> 0 | M7: =COUNTIFS('Risk Register'!$T$2:$T$22,4,'Risk Register'!$U$2:$U$22,5) -> 0
A8: 3 | B8: =COUNTIFS('Risk Register'!$K$2:$K$22,3,'Risk Register'!$L$2:$L$22,1) -> 1 | C8: =COUNTIFS('Risk Register'!$K$2:$K$22,3,'Risk Register'!$L$2:$L$22,2) -> 0 | D8: =COUNTIFS('Risk Register'!$K$2:$K$22,3,'Risk Register'!$L$2:$L$22,3) -> 2 | E8: =COUNTIFS('Risk Register'!$K$2:$K$22,3,'Risk Register'!$L$2:$L$22,4) -> 4 | F8: =COUNTIFS('Risk Register'!$K$2:$K$22,3,'Risk Register'!$L$2:$L$22,5) -> 4 | H8: 3 | I8: =COUNTIFS('Risk Register'!$T$2:$T$22,3,'Risk Register'!$U$2:$U$22,1) -> 1 | J8: =COUNTIFS('Risk Register'!$T$2:$T$22,3,'Risk Register'!$U$2:$U$22,2) -> 0 | K8: =COUNTIFS('Risk Register'!$T$2:$T$22,3,'Risk Register'!$U$2:$U$22,3) -> 0 | L8: =COUNTIFS('Risk Register'!$T$2:$T$22,3,'Risk Register'!$U$2:$U$22,4) -> 0 | M8: =COUNTIFS('Risk Register'!$T$2:$T$22,3,'Risk Register'!$U$2:$U$22,5) -> 0
A9: 2 | B9: =COUNTIFS('Risk Register'!$K$2:$K$22,2,'Risk Register'!$L$2:$L$22,1) -> 0 | C9: =COUNTIFS('Risk Register'!$K$2:$K$22,2,'Risk Register'!$L$2:$L$22,2) -> 0 | D9: =COUNTIFS('Risk Register'!$K$2:$K$22,2,'Risk Register'!$L$2:$L$22,3) -> 1 | E9: =COUNTIFS('Risk Register'!$K$2:$K$22,2,'Risk Register'!$L$2:$L$22,4) -> 1 | F9: =COUNTIFS('Risk Register'!$K$2:$K$22,2,'Risk Register'!$L$2:$L$22,5) -> 1 | H9: 2 | I9: =COUNTIFS('Risk Register'!$T$2:$T$22,2,'Risk Register'!$U$2:$U$22,1) -> 0 | J9: =COUNTIFS('Risk Register'!$T$2:$T$22,2,'Risk Register'!$U$2:$U$22,2) -> 2 | K9: =COUNTIFS('Risk Register'!$T$2:$T$22,2,'Risk Register'!$U$2:$U$22,3) -> 9 | L9: =COUNTIFS('Risk Register'!$T$2:$T$22,2,'Risk Register'!$U$2:$U$22,4) -> 1 | M9: =COUNTIFS('Risk Register'!$T$2:$T$22,2,'Risk Register'!$U$2:$U$22,5) -> 0
A10: 1 | B10: =COUNTIFS('Risk Register'!$K$2:$K$22,1,'Risk Register'!$L$2:$L$22,1) -> 0 | C10: =COUNTIFS('Risk Register'!$K$2:$K$22,1,'Risk Register'!$L$2:$L$22,2) -> 0 | D10: =COUNTIFS('Risk Register'!$K$2:$K$22,1,'Risk Register'!$L$2:$L$22,3) -> 0 | E10: =COUNTIFS('Risk Register'!$K$2:$K$22,1,'Risk Register'!$L$2:$L$22,4) -> 0 | F10: =COUNTIFS('Risk Register'!$K$2:$K$22,1,'Risk Register'!$L$2:$L$22,5) -> 0 | H10: 1 | I10: =COUNTIFS('Risk Register'!$T$2:$T$22,1,'Risk Register'!$U$2:$U$22,1) -> 1 | J10: =COUNTIFS('Risk Register'!$T$2:$T$22,1,'Risk Register'!$U$2:$U$22,2) -> 1 | K10: =COUNTIFS('Risk Register'!$T$2:$T$22,1,'Risk Register'!$U$2:$U$22,3) -> 1 | L10: =COUNTIFS('Risk Register'!$T$2:$T$22,1,'Risk Register'!$U$2:$U$22,4) -> 2 | M10: =COUNTIFS('Risk Register'!$T$2:$T$22,1,'Risk Register'!$U$2:$U$22,5) -> 3
A11: Empty cells contain no risks. Numbers show how many risks sit at each point.
A13: Risks by rating | H13: Appetite position
A14: Rating | B14: Current | C14: Target | H14: Risks above appetite today | L14: =COUNTIF('Risk Register'!$Y$2:$Y$22,"No") -> 17
A15: Critical | B15: =COUNTIF('Risk Register'!$N$2:$N$22,A15) -> 2 | C15: =COUNTIF('Risk Register'!$W$2:$W$22,A15) -> 0 | H15: Risks above appetite after treatment | L15: =COUNTIF('Risk Register'!$Z$2:$Z$22,"No") -> 0
A16: High | B16: =COUNTIF('Risk Register'!$N$2:$N$22,A16) -> 14 | C16: =COUNTIF('Risk Register'!$W$2:$W$22,A16) -> 0 | H16: Average current score | L16: =AVERAGE('Risk Register'!$M$2:$M$22) -> 12.809524
A17: Medium | B17: =COUNTIF('Risk Register'!$N$2:$N$22,A17) -> 4 | C17: =COUNTIF('Risk Register'!$W$2:$W$22,A17) -> 13 | H17: Average target score | L17: =AVERAGE('Risk Register'!$V$2:$V$22) -> 4.8571429
A18: Low | B18: =COUNTIF('Risk Register'!$N$2:$N$22,A18) -> 1 | C18: =COUNTIF('Risk Register'!$W$2:$W$22,A18) -> 8 | H18: Reduction in total risk score | L18: =1-SUM('Risk Register'!$V$2:$V$22)/SUM('Risk Register'!$M$2:$M$22) -> 0.62081784
A19: Total | B19: =SUM(B15:B18) -> 21 | C19: =SUM(C15:C18) -> 21
A21: Risks by owner
A22: Owner | B22: Risks | C22: Above appetite now
A23: Finance Director | B23: =COUNTIF('Risk Register'!$I$2:$I$22,A23) -> 2 | C23: =COUNTIFS('Risk Register'!$I$2:$I$22,A23,'Risk Register'!$Y$2:$Y$22,"No") -> 2
A24: Infrastructure Lead | B24: =COUNTIF('Risk Register'!$I$2:$I$22,A24) -> 8 | C24: =COUNTIFS('Risk Register'!$I$2:$I$22,A24,'Risk Register'!$Y$2:$Y$22,"No") -> 5
A25: Managing Director | B25: =COUNTIF('Risk Register'!$I$2:$I$22,A25) -> 3 | C25: =COUNTIFS('Risk Register'!$I$2:$I$22,A25,'Risk Register'!$Y$2:$Y$22,"No") -> 3
A26: Operations Director | B26: =COUNTIF('Risk Register'!$I$2:$I$22,A26) -> 4 | C26: =COUNTIFS('Risk Register'!$I$2:$I$22,A26,'Risk Register'!$Y$2:$Y$22,"No") -> 3
A27: Technical Director | B27: =COUNTIF('Risk Register'!$I$2:$I$22,A27) -> 4 | C27: =COUNTIFS('Risk Register'!$I$2:$I$22,A27,'Risk Register'!$Y$2:$Y$22,"No") -> 4
A30: Highest current risks
A31: Risk ID | B31: Title | H31: Owner | K31: Current | L31: Target | M31: Rating
A32: R-001 | B32: =INDEX('Risk Register'!$B$2:$B$22,MATCH($A32,'Risk Register'!$A$2:$A$22,0)) -> Compromise of privileged platform credentials leads to mass compromise of client environments | H32: =INDEX('Risk Register'!$I$2:$I$22,MATCH($A32,'Risk Register'!$A$2:$A$22,0)) -> Technical Director | K32: =INDEX('Risk Register'!$M$2:$M$22,MATCH($A32,'Risk Register'!$A$2:$A$22,0)) -> 20 | L32: =INDEX('Risk Register'!$V$2:$V$22,MATCH($A32,'Risk Register'!$A$2:$A$22,0)) -> 5 | M32: =INDEX('Risk Register'!$N$2:$N$22,MATCH($A32,'Risk Register'!$A$2:$A$22,0)) -> Critical
A33: R-012 | B33: =INDEX('Risk Register'!$B$2:$B$22,MATCH($A33,'Risk Register'!$A$2:$A$22,0)) -> Lantern fails to achieve ISO 27001 certification and keeps losing tenders | H33: =INDEX('Risk Register'!$I$2:$I$22,MATCH($A33,'Risk Register'!$A$2:$A$22,0)) -> Managing Director | K33: =INDEX('Risk Register'!$M$2:$M$22,MATCH($A33,'Risk Register'!$A$2:$A$22,0)) -> 20 | L33: =INDEX('Risk Register'!$V$2:$V$22,MATCH($A33,'Risk Register'!$A$2:$A$22,0)) -> 8 | M33: =INDEX('Risk Register'!$N$2:$N$22,MATCH($A33,'Risk Register'!$A$2:$A$22,0)) -> Critical
A34: R-002 | B34: =INDEX('Risk Register'!$B$2:$B$22,MATCH($A34,'Risk Register'!$A$2:$A$22,0)) -> Former employee retains privileged access to client platforms | H34: =INDEX('Risk Register'!$I$2:$I$22,MATCH($A34,'Risk Register'!$A$2:$A$22,0)) -> Operations Director | K34: =INDEX('Risk Register'!$M$2:$M$22,MATCH($A34,'Risk Register'!$A$2:$A$22,0)) -> 16 | L34: =INDEX('Risk Register'!$V$2:$V$22,MATCH($A34,'Risk Register'!$A$2:$A$22,0)) -> 4 | M34: =INDEX('Risk Register'!$N$2:$N$22,MATCH($A34,'Risk Register'!$A$2:$A$22,0)) -> High
A35: R-004 | B35: =INDEX('Risk Register'!$B$2:$B$22,MATCH($A35,'Risk Register'!$A$2:$A$22,0)) -> Uncontrolled script deployment causes a widespread client outage | H35: =INDEX('Risk Register'!$I$2:$I$22,MATCH($A35,'Risk Register'!$A$2:$A$22,0)) -> Infrastructure Lead | K35: =INDEX('Risk Register'!$M$2:$M$22,MATCH($A35,'Risk Register'!$A$2:$A$22,0)) -> 16 | L35: =INDEX('Risk Register'!$V$2:$V$22,MATCH($A35,'Risk Register'!$A$2:$A$22,0)) -> 6 | M35: =INDEX('Risk Register'!$N$2:$N$22,MATCH($A35,'Risk Register'!$A$2:$A$22,0)) -> High
A36: R-010 | B36: =INDEX('Risk Register'!$B$2:$B$22,MATCH($A36,'Risk Register'!$A$2:$A$22,0)) -> Malicious activity on privileged platforms goes undetected | H36: =INDEX('Risk Register'!$I$2:$I$22,MATCH($A36,'Risk Register'!$A$2:$A$22,0)) -> Infrastructure Lead | K36: =INDEX('Risk Register'!$M$2:$M$22,MATCH($A36,'Risk Register'!$A$2:$A$22,0)) -> 16 | L36: =INDEX('Risk Register'!$V$2:$V$22,MATCH($A36,'Risk Register'!$A$2:$A$22,0)) -> 6 | M36: =INDEX('Risk Register'!$N$2:$N$22,MATCH($A36,'Risk Register'!$A$2:$A$22,0)) -> High
A37: R-011 | B37: =INDEX('Risk Register'!$B$2:$B$22,MATCH($A37,'Risk Register'!$A$2:$A$22,0)) -> Incident response fails and notification deadlines are missed | H37: =INDEX('Risk Register'!$I$2:$I$22,MATCH($A37,'Risk Register'!$A$2:$A$22,0)) -> Technical Director | K37: =INDEX('Risk Register'!$M$2:$M$22,MATCH($A37,'Risk Register'!$A$2:$A$22,0)) -> 16 | L37: =INDEX('Risk Register'!$V$2:$V$22,MATCH($A37,'Risk Register'!$A$2:$A$22,0)) -> 6 | M37: =INDEX('Risk Register'!$N$2:$N$22,MATCH($A37,'Risk Register'!$A$2:$A$22,0)) -> High
A38: R-003 | B38: =INDEX('Risk Register'!$B$2:$B$22,MATCH($A38,'Risk Register'!$A$2:$A$22,0)) -> Excessive standing privilege allows misuse to go further and remain unattributed | H38: =INDEX('Risk Register'!$I$2:$I$22,MATCH($A38,'Risk Register'!$A$2:$A$22,0)) -> Technical Director | K38: =INDEX('Risk Register'!$M$2:$M$22,MATCH($A38,'Risk Register'!$A$2:$A$22,0)) -> 15 | L38: =INDEX('Risk Register'!$V$2:$V$22,MATCH($A38,'Risk Register'!$A$2:$A$22,0)) -> 6 | M38: =INDEX('Risk Register'!$N$2:$N$22,MATCH($A38,'Risk Register'!$A$2:$A$22,0)) -> High
A39: R-008 | B39: =INDEX('Risk Register'!$B$2:$B$22,MATCH($A39,'Risk Register'!$A$2:$A$22,0)) -> Security failure at a critical SaaS supplier | H39: =INDEX('Risk Register'!$I$2:$I$22,MATCH($A39,'Risk Register'!$A$2:$A$22,0)) -> Finance Director | K39: =INDEX('Risk Register'!$M$2:$M$22,MATCH($A39,'Risk Register'!$A$2:$A$22,0)) -> 15 | L39: =INDEX('Risk Register'!$V$2:$V$22,MATCH($A39,'Risk Register'!$A$2:$A$22,0)) -> 6 | M39: =INDEX('Risk Register'!$N$2:$N$22,MATCH($A39,'Risk Register'!$A$2:$A$22,0)) -> High
A41: Risks still above appetite after treatment
A42: None. R-008 was the only risk above appetite in v1.0. It was brought within appetite by the treatment agreed after third party assessment TPRA-001, with interim acceptance requested until that treatment is complete.
A43: This list is reviewed by the Managing Director. Each item needs either a formal acceptance or additional treatment.

Sheet Methodology
A1: Risk Assessment Methodology
A2: How risks in this register are identified, scored, compared with appetite and treated
A4: 1. Approach
A5: Risks are identified by asset and threat. For each information asset in scope, the assessor asks what could happen to it, who or what would cause it, and which weakness would allow it. Each risk is written as cause, event and consequence so that the owner can see exactly what they are being asked to manage.
A6: Risks are scored on their current level, meaning with the controls that actually operate today. Inherent risk (risk with no controls at all) is not scored. ISO/IEC 27001 does not require it, it is hypothetical for an organisation that already runs controls, and in practice it tends to be guessed. Scoring current and target risk gives the board the two numbers it needs: where we are and where the treatment plan will take us.
A8: 2. Likelihood scale (over the next 12 months)
A9: Score | B9: Level | C9: Description | D9: Indicative probability
A10: 1 | B10: Rare | C10: Would require an unusual combination of events. No known occurrence in comparable MSPs. | D10: Under 5%
A11: 2 | B11: Unlikely | C11: Could happen, but controls or circumstances make it improbable. | D11: 5% to 20%
A12: 3 | B12: Possible | C12: Has happened to comparable organisations. Weaknesses exist that would allow it. | D12: 20% to 50%
A13: 4 | B13: Likely | C13: Expected to happen at some point in the year, or has already happened at Lantern. | D13: 50% to 80%
A14: 5 | B14: Almost certain | C14: Expected to happen, or is already happening. | D14: Over 80%
A16: 3. Impact scale (score the highest dimension that applies)
A17: Score | B17: Level | C17: Financial | D17: Clients and service | E17: Regulatory and legal | F17: Reputation
A18: 1 | B18: Negligible | C18: Under £10k | D18: No client noticeable impact | E18: No regulatory interest | F18: No external awareness
A19: 2 | B19: Minor | C19: £10k to £50k | D19: One client affected for under a day | E19: Internal record only, no reportable breach | F19: Single client complaint
A20: 3 | B20: Moderate | C20: £50k to £250k | D20: Several clients affected or one client for several days; SLA credits | E20: Reportable breach with limited ICO follow up | F20: Local or trade press; several complaints
A21: 4 | B21: Major | C21: £250k to £1m | D21: Many clients affected; some contracts lost | E21: ICO investigation or regulator enforcement notice | F21: National trade press; loss of tenders
A22: 5 | B22: Severe | C22: Over £1m (12% or more of turnover) | D22: Simultaneous impact across the client base; loss of 10% or more of clients | E22: Significant fine or turnover based penalty | F22: National press; long term loss of trust
A24: 4. Risk score and rating
A25: Risk score = likelihood x impact, giving a value from 1 to 25. The score maps to a rating as follows.
A26: Score | B26: Rating | C26: Meaning | D26: Required response
A27: 20 to 25 | B27: Critical | C27: Unacceptable in any category | D27: Immediate treatment. Cannot be accepted. Reported to the Managing Director within 5 working days.
A28: 10 to 16 | B28: High | C28: Above appetite in every category except Strategic | D28: Treatment plan agreed within 1 month. Acceptance only by the Managing Director.
A29: 5 to 9 | B29: Medium | C29: Within appetite for some categories | D29: Treat or accept depending on category appetite. Acceptance by the risk owner.
A30: 1 to 4 | B30: Low | C30: Within appetite for all categories | D30: Accept and monitor through the normal review cycle.
A32: 5. Risk matrix
A33: Likelihood / Impact | B33: 1 | C33: 2 | D33: 3 | E33: 4 | F33: 5
A34: 5 | B34: 5 | C34: 10 | D34: 15 | E34: 20 | F34: 25
A35: 4 | B35: 4 | C35: 8 | D35: 12 | E35: 16 | F35: 20
A36: 3 | B36: 3 | C36: 6 | D36: 9 | E36: 12 | F36: 15
A37: 2 | B37: 2 | C37: 4 | D37: 6 | E37: 8 | F37: 10
A38: 1 | B38: 1 | C38: 2 | D38: 3 | E38: 4 | F38: 5
A40: 6. Risk appetite by category
A41: Appetite is set by the Managing Director and differs by category. Lantern's business depends on clients trusting it with administrative access, so appetite for risks to that trust is low. Appetite for commercial risk is higher because the business must keep taking on new clients and projects. The maximum acceptable score below drives the appetite columns on the Risk Register.
A42: Category | B42: Appetite | C42: Appetite statement | D42: Max acceptable score
A43: Client Trust & Privileged Access | B43: Low | C43: Lantern will not accept risks that could expose client environments or client credentials beyond a Medium rating of 6. | D43: 6
A44: Regulatory & Legal | B44: Low | C44: Lantern will meet its legal and contractual obligations and will not accept a Medium risk above 6 of regulatory breach. | D44: 6
A45: Operational Resilience | B45: Moderate | C45: Lantern accepts some disruption to its own operations where the cost of further control is disproportionate. | D45: 9
A46: Strategic & Commercial | B46: Open | C46: Lantern accepts commercial risk in pursuit of growth, provided it is understood and owned. | D46: 12
...

Sheet Risk Register
A1: Risk ID | B1: Risk title | C1: Category | D1: Risk description (cause, event, consequence) | E1: Assets affected | F1: Threat | G1: Vulnerability | H1: CIA | I1: Risk owner | J1: Existing controls | K1: Current likelihood | L1: Current impact | M1: Current score | N1: Current rating | O1: Scoring rationale | P1: Treatment option | Q1: Treatment plan | R1: Annex A controls | S1: Gap assessment refs | T1: Target likelihood | U1: Target impact | V1: Target score | W1: Target rating | X1: Appetite threshold | Y1: Current within appetite | Z1: Target within appetite | AA1: Target date | AB1: Status | AC1: Last reviewed | AD1: Next review due | AE1: Notes
A2: R-001 | B2: Compromise of privileged platform credentials leads to mass compromise of client environments | C2: Client Trust & Privileged Access | D2: An attacker obtains an engineer's password for the RMM platform or backup console through phishing, password reuse or infostealer malware. Because neither platform enforces MFA, the attacker logs in and uses legitimate remote access and scripting to deploy ransomware across client endpoints and delete client backups. | E2: RMM platform; backup console; c.3,200 client endpoints; client backup data | F2: External attacker (organised ransomware group) | G2: No MFA on RMM platform or backup console; shared engineer credentials on six client tenancies | H2: C, I, A | I2: Technical Director | J2: MFA enforced on Microsoft 365 only; Defender for Endpoint P1 on Lantern laptops; engineers use a password manager | K2: 4 | L2: 5 | M2: =K2*L2 -> 20 | N2: =IF(M2>=20,"Critical",IF(M2>=10,"High",IF(M2>=5,"Medium","Low"))) -> Critical | O2: Likely: attacks on MSP remote management tooling are common and one stolen password is enough. Severe: simultaneous impact across 140 clients, likely loss of a large share of the client base, plus ICO and contractual exposure. | P2: Treat | Q2: Enforce phishing resistant MFA on the RMM platform and backup console as an emergency change. Remove shared credentials. Restrict admin console access by conditional access or IP allow list. Alert on new device sign in and mass script execution. | R2: A.5.15, A.5.17, A.8.2, A.8.5, A.8.16 | S2: GAP-030, GAP-016, GAP-032 | T2: 1 | U2: 5 | V2: =T2*U2 -> 5 | W2: =IF(V2>=20,"Critical",IF(V2>=10,"High",IF(V2>=5,"Medium","Low"))) -> Medium | X2: =INDEX(Methodology!$D$43:$D$46,MATCH(C2,Methodology!$A$43:$A$46,0)) -> 6 | Y2: =IF(M2<=X2,"Yes","No") -> No | Z2: =IF(V2<=X2,"Yes","No") -> Yes | AA2: 46626 | AB2: Open: treatment planned | AC2: 46322 | AD2: =AC2+IF(OR(N2="Critical",N2="High"),30,91) -> 46352 | AE2: Impact stays at 5 because a successful attack would still be severe. Treatment works on likelihood.
A3: R-002 | B3: Former employee retains privileged access to client platforms | C3: Client Trust & Privileged Access | D3: The leaver process does not reliably remove accounts. A former engineer, or an attacker who has obtained a former engineer's credentials, uses an account that is still active to access client environments without being noticed. | E3: RMM platform; credential vault; backup console; Partner Center; PSA | F3: Disgruntled former employee; external attacker using stale credentials | G3: No leaver checklist covering client platforms; no verification step; no access reviews; no monitoring of dormant accounts | H3: C, I, A | I3: Operations Director | J3: HR emails IT about leavers; Entra ID account disabled on the last working day | K3: 4 | L3: 4 | M3: =K3*L3 -> 16 | N3: =IF(M3>=20,"Critical",IF(M3>=10,"High",IF(M3>=5,"Medium","Low"))) -> High | O3: Likely: the failure has already happened, with two RMM accounts still active three months after the engineers left. Major rather than severe because misuse by one individual is more likely to be targeted than estate wide. | P3: Treat | Q3: Audit every account on the critical platforms against the HR roster now. Introduce a leaver checklist naming every platform, a 4 hour revocation target and sign off by the Technical Director. Run quarterly access reviews. Move client platforms to Entra ID single sign on where supported so one disablement removes all access. | R3: A.5.16, A.5.18, A.6.5, A.8.2 | S3: GAP-021, GAP-016, GAP-006 | T3: 1 | U3: 4 | V3: =T3*U3 -> 4 | W3: =IF(V3>=20,"Critical",IF(V3>=10,"High",IF(V3>=5,"Medium","Low"))) -> Low | X3: =INDEX(Methodology!$D$43:$D$46,MATCH(C3,Methodology!$A$43:$A$46,0)) -> 6 | Y3: =IF(M3<=X3,"Yes","No") -> No | Z3: =IF(V3<=X3,"Yes","No") -> Yes | AA3: 46477 | AB3: Open: treatment planned | AC3: 46322 | AD3: =AC3+IF(OR(N3="Critical",N3="High"),30,91) -> 46352 | AE3: Log the original failure as a nonconformity under Clause 10.2 so the record shows corrective action.
A4: R-003 | B4: Excessive standing privilege allows misuse to go further and remain unattributed | C4: Client Trust & Privileged Access | D4: Engineers hold more access than their roles need: three engineers have permanent full access to the credential vault, 41 clients are still on legacy full delegated admin, and shared accounts are used on six tenancies. If any account is compromised or misused, the reach is far wider than necessary and actions cannot be traced to a person. | E4: Credential vault; client Microsoft 365 tenancies; Partner Center | F4: Compromised engineer account; malicious insider; human error | G4: No access control policy; no least privilege model; legacy delegated admin; shared credentials; no break glass model for the vault | H4: C, I | I4: Technical Director | J4: Vault requires individual login; 99 clients already on granular delegated admin (GDAP) | K4: 3 | L4: 5 | M4: =K4*L4 -> 15 | N4: =IF(M4>=20,"Critical",IF(M4>=10,"High",IF(M4>=5,"Medium","Low"))) -> High | O4: Possible: needs a separate compromise or insider act first, but standing access makes any such event high impact straight away. Severe: full vault access exposes administrative credentials for all 140 clients. | P4: Treat | Q4: Write an access control policy. Finish the GDAP migration for the remaining 41 clients. Replace shared accounts. Introduce just in time elevation for the vault with monitored break glass accounts. Quarterly access reviews. | R4: A.5.15, A.5.16, A.5.18, A.8.2, A.8.3 | S4: GAP-016 | T4: 2 | U4: 3 | V4: =T4*U4 -> 6 | W4: =IF(V4>=20,"Critical",IF(V4>=10,"High",IF(V4>=5,"Medium","Low"))) -> Medium | X4: =INDEX(Methodology!$D$43:$D$46,MATCH(C4,Methodology!$A$43:$A$46,0)) -> 6 | Y4: =IF(M4<=X4,"Yes","No") -> No | Z4: =IF(V4<=X4,"Yes","No") -> Yes | AA4: 46535 | AB4: Open: treatment planned | AC4: 46322 | AD4: =AC4+IF(OR(N4="Critical",N4="High"),30,91) -> 46352 | AE4: Impact falls once access is scoped, because one compromised account no longer reaches every client.
A5: R-004 | B5: Uncontrolled script deployment causes a widespread client outage | C5: Operational Resilience | D5: Engineers push scripts to client estates through the RMM without review, testing or approval. A faulty script, or one run against the wrong device group, executes on thousands of endpoints at once and causes outages or data loss for several clients. | E5: RMM platform; client endpoints; client service availability | F5: Human error; malicious insider | G5: No change management; scripts not version controlled or peer reviewed; no pilot group; no rollback plans | H5: I, A | I5: Infrastructure Lead | J5: Experienced engineers; RMM allows targeting by device group | K5: 4 | L5: 4 | M5: =K5*L5 -> 16 | N5: =IF(M5>=20,"Critical",IF(M5>=10,"High",IF(M5>=5,"Medium","Low"))) -> High | O5: Likely: scripts go out every week with no review, so an error within 12 months is more likely than not. Major: multi client outage with SLA credits and reputational damage, though normally recoverable. | P5: Treat | Q5: Introduce change management with standard, normal and emergency categories. Peer review and approval for any script touching more than one client. Version controlled script repository. Internal pilot group before wider release. Rollback plan for normal changes. All changes logged in the PSA. | R5: A.8.25, A.8.31, A.8.32 | S5: GAP-031, GAP-038 | T5: 2 | U5: 3 | V5: =T5*U5 -> 6 | W5: =IF(V5>=20,"Critical",IF(V5>=10,"High",IF(V5>=5,"Medium","Low"))) -> Medium | X5: =INDEX(Methodology!$D$43:$D$46,MATCH(C5,Methodology!$A$43:$A$46,0)) -> 9 | Y5: =IF(M5<=X5,"Yes","No") -> No | Z5: =IF(V5<=X5,"Yes","No") -> Yes | AA5: 46507 | AB5: Open: treatment planned | AC5: 46322 | AD5: =AC5+IF(OR(N5="Critical",N5="High"),30,91) -> 46352
A6: R-005 | B6: Ransomware spreads through Lantern's own corporate environment | C6: Operational Resilience | D6: Malware gets in through an unmanaged lab device or an unpatched internal system and spreads across the flat office network, encrypting Lantern's own systems including the legacy Hyper-V host. The service desk cannot operate and service to all clients is disrupted. | E6: Corporate laptops; legacy Hyper-V host; office network; Lantern internal data | F6: Ransomware operators; commodity malware | G6: Flat network with no segregation; seven unmanaged lab devices; inconsistent internal patching; no vulnerability scanning | H6: C, I, A | I6: Infrastructure Lead | J6: Defender for Endpoint P1 and Intune compliance on managed devices; Defender for Office 365 P1 | K6: 3 | L6: 4 | M6: =K6*L6 -> 12 | N6: =IF(M6>=20,"Critical",IF(M6>=10,"High",IF(M6>=5,"Medium","Low"))) -> High | O6: Possible: managed laptops are reasonably protected, but the unmanaged devices and flat network give an easy path once a foothold exists. Major: loss of internal systems stops the service desk for every client. | P6: Treat | Q6: Segregate the network into corporate, lab and guest VLANs. Bring lab devices under Intune or isolate them. Introduce vulnerability scanning and remediation targets by severity. Migrate and decommission the legacy host. | R6: A.8.7, A.8.8, A.8.20, A.8.22 | S6: GAP-034, GAP-033, GAP-026 | T6: 2 | U6: 3 | V6: =T6*U6 -> 6 | W6: =IF(V6>=20,"Critical",IF(V6>=10,"High",IF(V6>=5,"Medium","Low"))) -> Medium | X6: =INDEX(Methodology!$D$43:$D$46,MATCH(C6,Methodology!$A$43:$A$46,0)) -> 9 | Y6: =IF(M6<=X6,"Yes","No") -> No | Z6: =IF(V6<=X6,"Yes","No") -> Yes | AA6: 46626 | AB6: Open: treatment planned | AC6: 46322 | AD6: =AC6+IF(OR(N6="Critical",N6="High"),30,91) -> 46352
A7: R-006 | B7: Personal data breach involving client data | C7: Regulatory & Legal | D7: Client data, including special category health data held for healthcare clients, leaves the organisation by mistake or on purpose because there is no classification scheme and no data loss prevention. The breach has to be reported to the ICO and to the affected clients. | E7: Ticketing data; client documentation; client backup data | F7: Staff error; malicious insider | G7: No classification scheme; Microsoft 365 DLP not enabled; removable media not restricted | H7: C | I7: Technical Director | J7: Defender for Office 365 P1; BitLocker on laptops | K7: 3 | L7: 4 | M7: =K7*L7 -> 12 | N7: =IF(M7>=20,"Critical",IF(M7>=10,"High",IF(M7>=5,"Medium","Low"))) -> High | O7: Possible: staff handle client data every day with no technical guardrail. Major: special category data raises ICO exposure and healthcare clients would be likely to leave. | P7: Treat | Q7: Adopt a four level classification scheme and handling rules. Apply sensitivity labels. Run Microsoft 365 DLP in audit mode, then enforce. Block removable media through Intune. Cover data handling in awareness training. | R7: A.5.12, A.5.13, A.5.34, A.8.12 | S7: GAP-015, GAP-037, GAP-011 | T7: 2 | U7: 3 | V7: =T7*U7 -> 6 | W7: =IF(V7>=20,"Critical",IF(V7>=10,"High",IF(V7>=5,"Medium","Low"))) -> Medium | X7: =INDEX(Methodology!$D$43:$D$46,MATCH(C7,Methodology!$A$43:$A$46,0)) -> 6 | Y7: =IF(M7<=X7,"Yes","No") -> No | Z7: =IF(V7<=X7,"Yes","No") -> Yes | AA7: 46660 | AB7: Open: treatment planned | AC7: 46322 | AD7: =AC7+IF(OR(N7="Critical",N7="High"),30,91) -> 46352
A8: R-007 | B8: Processor obligations not met on legacy client contracts | C8: Regulatory & Legal | D8: 22 client contracts date from before 2019 and do not include UK GDPR Article 28 processor terms, and no Article 30 records of processing exist. Lantern is processing personal data without the required contractual basis, which exposes it to ICO action and to disputes with clients if a breach happens. | E8: Client contracts; client personal data | F8: Regulatory enforcement; client legal claim | G8: Contracts never refreshed; no legal and regulatory register; no accountable data protection role | H8: C | I8: Finance Director | J8: Article 28 terms present in 118 of 140 contracts | K8: 3 | L8: 3 | M8: =K8*L8 -> 9 | N8: =IF(M8>=20,"Critical",IF(M8>=10,"High",IF(M8>=5,"Medium","Low"))) -> Medium | O8: Possible: the gap only bites if there is a breach or audit, but any client audit would find it. Moderate: ICO action over a contract gap alone is unlikely to be large, but liability in a breach would be unclear. | P8: Treat | Q8: Issue a data processing addendum to the 22 clients. Build a legal and regulatory register. Produce Article 30 records. Name an accountable data protection lead. | R8: A.5.31, A.5.34 | S8: GAP-019 | T8: 1 | U8: 3 | V8: =T8*U8 -> 3 | W8: =IF(V8>=20,"Critical",IF(V8>=10,"High",IF(V8>=5,"Medium","Low"))) -> Low | X8: =INDEX(Methodology!$D$43:$D$46,MATCH(C8,Methodology!$A$43:$A$46,0)) -> 6 | Y8: =IF(M8<=X8,"Yes","No") -> No | Z8: =IF(V8<=X8,"Yes","No") -> Yes | AA8: 46507 | AB8: Open: treatment planned | AC8: 46322 | AD8: =AC8+IF(OR(N8="Critical",N8="High"),30,91) -> 46413 | AE8: Contract sample was 10 of 140; confirm the count of 22 by full review.
A9: R-008 | B9: Security failure at a critical SaaS supplier | C9: Client Trust & Privileged Access | D9: The credential vault, RMM, PSA or backup supplier suffers a breach or a long outage. Because the vault holds administrative credentials for every client and the RMM reaches every managed endpoint, a breach at the supplier becomes a breach of Lantern's clients. Lantern has never assessed these suppliers. | E9: Credential vault; RMM platform; PSA; backup platform | F9: Supply chain attack on the vendor; vendor outage | G9: No supplier register; no due diligence; no security terms in contracts; no exit plans | H9: C, I, A | I9: Finance Director | J9: Suppliers are established vendors; DPA in place with the backup supplier | K9: 3 | L9: 5 | M9: =K9*L9 -> 15 | N9: =IF(M9>=20,"Critical",IF(M9>=10,"High",IF(M9>=5,"Medium","Low"))) -> High | O9: Possible: MSP software vendors have been breached before and Lantern has no view of its suppliers' controls. Severe: the vault holds credentials for every client environment. | P9: Treat | Q9: Build a supplier register with criticality tiers. Fully assess the four critical suppliers, starting with the credential vault (done: TPRA-001). Harden Lantern's use of the vault with enforced MFA, SSO, least privilege and IP restriction. Agree a security schedule with 24 hour incident notification at renewal. Reduce what the vault holds by removing tenant admin credentials after GDAP and deploying Windows LAPS. Document exit plans. Reassess annually. | R9: A.5.19, A.5.20, A.5.21, A.5.22, A.5.23 | S9: GAP-012, GAP-020; TPRA-001 | T9: 2 | U9: 3 | V9: =T9*U9 -> 6 | W9: =IF(V9>=20,"Critical",IF(V9>=10,"High",IF(V9>=5,"Medium","Low"))) -> Medium | X9: =INDEX(Methodology!$D$43:$D$46,MATCH(C9,Methodology!$A$43:$A$46,0)) -> 6 | Y9: =IF(M9<=X9,"Yes","No") -> No | Z9: =IF(V9<=X9,"Yes","No") -> Yes | AA9: 46598 | AB9: Open: treatment planned | AC9: 46322 | AD9: =AC9+IF(OR(N9="Critical",N9="High"),30,91) -> 46352 | AE9: Updated after third party assessment TPRA-001 (Oct 2026). Supplier controls are adequate but keys are supplier held, so impact only falls once the vault stops holding tenant admin credentials (TP-43). Until then the residual is 10, above appetite, and interim acceptance by the Managing Director is requested to 30 Jul 2027.
A10: R-009 | B10: Data cannot be restored after ransomware or malicious deletion | C10: Operational Resilience | D10: Backup jobs are checked for success, but restores are not tested and immutability has not been confirmed. After ransomware or a deletion through the backup console, client or Lantern data cannot be recovered in an acceptable time, or at all. | E10: Client backup data; Lantern corporate backups; backup console | F10: Ransomware operator targeting backups; technical failure; human error | G10: No restore testing; immutability not verified; no backup policy; console has no MFA | H10: I, A | I10: Infrastructure Lead | J10: Daily backup jobs with success monitoring; UK region SaaS platform | K10: 3 | L10: 5 | M10: =K10*L10 -> 15 | N10: =IF(M10>=20,"Critical",IF(M10>=10,"High",IF(M10>=5,"Medium","Low"))) -> High | O10: Possible: ransomware groups go after backups first and restorability has never been proven. Severe: managed backup is a contracted service, so a failed restore would end client relationships and invite legal claims. | P10: Treat | Q10: Write a backup policy. Enable and verify immutability. Restore test Lantern's own data now, then run quarterly sampled client restore tests. Define RTO and RPO per service. MFA on the console is covered under R-001. | R10: A.5.30, A.8.13, A.8.14 | S10: GAP-035, GAP-018, GAP-030 | T10: 1 | U10: 4 | V10: =T10*U10 -> 4 | W10: =IF(V10>=20,"Critical",IF(V10>=10,"High",IF(V10>=5,"Medium","Low"))) -> Low | X10: =INDEX(Methodology!$D$43:$D$46,MATCH(C10,Methodology!$A$43:$A$46,0)) -> 9 | Y10: =IF(M10<=X10,"Yes","No") -> No | Z10: =IF(V10<=X10,"Yes","No") -> Yes | AA10: 46477 | AB10: Open: treatment planned | AC10: 46322 | AD10: =AC10+IF(OR(N10="Critical",N10="High"),30,91) -> 46352
A11: R-010 | B11: Malicious activity on privileged platforms goes undetected | C11: Operational Resilience | D11: Logs from the RMM, credential vault and backup console are not collected or reviewed and nothing raises an alert. An attacker or insider misusing privileged access can operate for weeks before anyone notices, which makes every other incident worse. | E11: RMM platform; credential vault; backup console; Entra ID | F11: External attacker; malicious insider | G11: No SIEM; no alerting; 90 day retention; logs only reviewed during investigations | H11: C, I, A | I11: Infrastructure Lead | J11: Entra ID and Microsoft 365 audit logs kept for 90 days; Defender alerts on managed laptops | K11: 4 | L11: 4 | M11: =K11*L11 -> 16 | N11: =IF(M11>=20,"Critical",IF(M11>=10,"High",IF(M11>=5,"Medium","Low"))) -> High | O11: Likely: detection currently depends on luck, as shown by stale accounts going unnoticed for three months. Major: a long dwell time multiplies the impact of every other risk in this register. | P11: Treat | Q11: Deploy Microsoft Sentinel with connectors for Entra ID, Microsoft 365, RMM, vault and backup console. Keep logs for 12 months. Build a minimum alert set (vault access, privileged role changes, MFA changes, impossible travel, mass script runs, backup deletion). Assign daily triage. | R11: A.8.15, A.8.16 | S11: GAP-032 | T11: 2 | U11: 3 | V11: =T11*U11 -> 6 | W11: =IF(V11>=20,"Critical",IF(V11>=10,"High",IF(V11>=5,"Medium","Low"))) -> Medium | X11: =INDEX(Methodology!$D$43:$D$46,MATCH(C11,Methodology!$A$43:$A$46,0)) -> 9 | Y11: =IF(M11<=X11,"Yes","No") -> No | Z11: =IF(V11<=X11,"Yes","No") -> Yes | AA11: 46660 | AB11: Open: treatment planned | AC11: 46322 | AD11: =AC11+IF(OR(N11="Critical",N11="High"),30,91) -> 46352
A12: R-011 | B12: Incident response fails and notification deadlines are missed | C12: Regulatory & Legal | D12: There is no incident response plan, classification or set of roles. When a serious incident happens the response is improvised, evidence is lost and Lantern fails to notify the ICO within 72 hours or, once the Cyber Security and Resilience Bill is in force, its regulator within 24 hours. | E12: All in scope assets | F12: Any security incident | G12: No IR plan; no security category in the PSA; no evidence handling; no exercises | H12: C, I, A | I12: Technical Director | J12: Experienced engineers; incidents handled as ordinary service desk tickets | K12: 4 | L12: 4 | M12: =K12*L12 -> 16 | N12: =IF(M12>=20,"Critical",IF(M12>=10,"High",IF(M12>=5,"Medium","Low"))) -> High | O12: Likely: an MSP of this size should expect at least one incident needing a structured response each year, and there is no way to recognise a reportable event. Major: penalty for late notification on top of a worse incident. | P12: Treat | Q12: Write an incident response plan with a notification decision tree for UK GDPR and the CSR Bill. Add a security category and severity field to the PSA. Define evidence preservation steps. Run a tabletop exercise on compromised RMM credentials. Hold a post incident review after every significant incident. | R12: A.5.24, A.5.25, A.5.26, A.5.27, A.5.28, A.6.8 | S12: GAP-013, GAP-025 | T12: 2 | U12: 3 | V12: =T12*U12 -> 6 | W12: =IF(V12>=20,"Critical",IF(V12>=10,"High",IF(V12>=5,"Medium","Low"))) -> Medium | X12: =INDEX(Methodology!$D$43:$D$46,MATCH(C12,Methodology!$A$43:$A$46,0)) -> 6 | Y12: =IF(M12<=X12,"Yes","No") -> No | Z12: =IF(V12<=X12,"Yes","No") -> Yes | AA12: 46535 | AB12: Open: treatment planned | AC12: 46322 | AD12: =AC12+IF(OR(N12="Critical",N12="High"),30,91) -> 46352
A13: R-012 | B13: Lantern fails to achieve ISO 27001 certification and keeps losing tenders | C13: Strategic & Commercial | D13: Without a working ISMS, Lantern misses its certification target and continues to be excluded from tenders that require ISO/IEC 27001. | E13: Revenue pipeline; reputation with prospective clients | F13: Competitors who hold certification; tender requirements | G13: No ISMS scope, risk process, SoA, internal audit or management review; nobody resourced to deliver it | H13: N/A | I13: Managing Director | J13: Board approved certification objective; Cyber Essentials held | K13: 5 | L13: 4 | M13: =K13*L13 -> 20 | N13: =IF(M13>=20,"Critical",IF(M13>=10,"High",IF(M13>=5,"Medium","Low"))) -> Critical | O13: Almost certain on the current path: readiness is 24% and no one is assigned to the work. Major: about £620k of annual contract value has already been lost to this requirement. | P13: Treat | Q13: Appoint an Information Security Manager. Deliver roadmap phases 1 to 5 from the gap assessment. Consider external implementation support if the Q3 2027 target is to be protected. | R13: A.5.1, A.5.2, A.5.35; Clauses 4 to 10 | S13: GAP-001, GAP-002, GAP-003, GAP-004, GAP-005, GAP-008 | T13: 2 | U13: 4 | V13: =T13*U13 -> 8 | W13: =IF(V13>=20,"Critical",IF(V13>=10,"High",IF(V13>=5,"Medium","Low"))) -> Medium | X13: =INDEX(Methodology!$D$43:$D$46,MATCH(C13,Methodology!$A$43:$A$46,0)) -> 12 | Y13: =IF(M13<=X13,"Yes","No") -> No | Z13: =IF(V13<=X13,"Yes","No") -> Yes | AA13: 46738 | AB13: Open: treatment planned | AC13: 46322 | AD13: =AC13+IF(OR(N13="Critical",N13="High"),30,91) -> 46352 | AE13: Business risk included deliberately so the board sees certification in the same terms as the security risks.
A14: R-013 | B14: Security depends on one person, the Technical Director | C14: Operational Resilience | D14: All security knowledge and decisions sit with the Technical Director on top of a full operational role. If that person is absent, leaves or is overloaded, the security programme stalls and incidents have no owner. | E14: ISMS programme; incident response capability | F14: Departure, illness or overload of a key person | G14: No defined security roles; no deputy; knowledge not written down | H14: A | I14: Managing Director | J14: None | K14: 3 | L14: 4 | M14: =K14*L14 -> 12 | N14: =IF(M14>=20,"Critical",IF(M14>=10,"High",IF(M14>=5,"Medium","Low"))) -> High | O14: Possible: the workload is already more than one role can carry. Major: programme delivery and incident handling both depend on one individual. | P14: Treat | Q14: Appoint an Information Security Manager. Publish a responsibility matrix. Document key procedures. Name a deputy incident coordinator. | R14: A.5.2, A.5.3 | S14: GAP-008 | T14: 2 | U14: 2 | V14: =T14*U14 -> 4 | W14: =IF(V14>=20,"Critical",IF(V14>=10,"High",IF(V14>=5,"Medium","Low"))) -> Low | X14: =INDEX(Methodology!$D$43:$D$46,MATCH(C14,Methodology!$A$43:$A$46,0)) -> 9 | Y14: =IF(M14<=X14,"Yes","No") -> No | Z14: =IF(V14<=X14,"Yes","No") -> Yes | AA14: 46444 | AB14: Open: treatment planned | AC14: 46322 | AD14: =AC14+IF(OR(N14="Critical",N14="High"),30,91) -> 46352
A15: R-014 | B15: Known vulnerability in client facing tooling is exploited before it is patched | C15: Client Trust & Privileged Access | D15: A critical vulnerability is published for the RMM platform, the backup software or an internet facing system. Without a threat intelligence process or patch targets, Lantern does not act before attackers exploit it. | E15: RMM agents and server; backup platform; internet facing systems | F15: Opportunistic and targeted attackers using published vulnerabilities | G15: No threat intelligence process; no remediation targets; no vulnerability scanning of the internal estate | H15: C, I, A | I15: Infrastructure Lead | J15: Client patching automated through the RMM; some engineers receive vendor emails | K15: 3 | L15: 5 | M15: =K15*L15 -> 15 | N15: =IF(M15>=20,"Critical",IF(M15>=10,"High",IF(M15>=5,"Medium","Low"))) -> High | O15: Possible: RMM vulnerabilities have been mass exploited within days of disclosure. Severe: the same estate wide reach as R-001. | P15: Treat | Q15: Subscribe to NCSC Early Warning and vendor security advisories with a weekly review. Set remediation targets (critical in 7 days, actively exploited within 48 hours through an emergency change). Scan the internal estate. | R15: A.5.7, A.8.8 | S15: GAP-017, GAP-033 | T15: 1 | U15: 5 | V15: =T15*U15 -> 5 | W15: =IF(V15>=20,"Critical",IF(V15>=10,"High",IF(V15>=5,"Medium","Low"))) -> Medium | X15: =INDEX(Methodology!$D$43:$D$46,MATCH(C15,Methodology!$A$43:$A$46,0)) -> 6 | Y15: =IF(M15<=X15,"Yes","No") -> No | Z15: =IF(V15<=X15,"Yes","No") -> Yes | AA15: 46598 | AB15: Open: treatment planned | AC15: 46322 | AD15: =AC15+IF(OR(N15="Critical",N15="High"),30,91) -> 46352
A16: R-015 | B16: Staff are deceived by phishing or impersonation | C16: Operational Resilience | D16: Staff, especially service desk engineers who handle password resets and access requests, are tricked by phishing emails or by callers pretending to be client staff. This leads to stolen credentials or unauthorised changes in client environments. | E16: Staff accounts; client accounts administered by the service desk | F16: Phishing; vishing; impersonation of client staff | G16: Awareness limited to an annual phishing test with 61% completion; no caller verification procedure; no web filtering; no safe reporting route | H16: C, I | I16: Operations Director | J16: Defender for Office 365 P1; MFA on Microsoft 365 | K16: 4 | L16: 3 | M16: =K16*L16 -> 12 | N16: =IF(M16>=20,"Critical",IF(M16>=10,"High",IF(M16>=5,"Medium","Low"))) -> High | O16: Likely: the service desk takes a high volume of requests and help desk social engineering is a common attack technique. Moderate: MFA on Microsoft 365 limits what a stolen Lantern password can do on its own. | P16: Treat | Q16: Quarterly role based awareness training with more depth for privileged engineers. Caller verification procedure for resets and access changes. Enable Defender web content filtering. Publish a no blame reporting route. | R16: A.6.3, A.6.8, A.8.23 | S16: GAP-011, GAP-025, GAP-040 | T16: 2 | U16: 3 | V16: =T16*U16 -> 6 | W16: =IF(V16>=20,"Critical",IF(V16>=10,"High",IF(V16>=5,"Medium","Low"))) -> Medium | X16: =INDEX(Methodology!$D$43:$D$46,MATCH(C16,Methodology!$A$43:$A$46,0)) -> 9 | Y16: =IF(M16<=X16,"Yes","No") -> No | Z16: =IF(V16<=X16,"Yes","No") -> Yes | AA16: 46568 | AB16: Open: treatment planned | AC16: 46322 | AD16: =AC16+IF(OR(N16="Critical",N16="High"),30,91) -> 46352
A17: R-016 | B17: Laptop is lost or stolen | C17: Operational Resilience | D17: A laptop is lost or stolen while a member of staff is working remotely or travelling. | E17: Laptops; data cached locally | F17: Theft; loss | G17: Mobile workforce | H17: C | I17: Infrastructure Lead | J17: BitLocker enforced; Intune managed with remote wipe; MFA and conditional access; data held in Microsoft 365 rather than locally | K17: 3 | L17: 1 | M17: =K17*L17 -> 3 | N17: =IF(M17>=20,"Critical",IF(M17>=10,"High",IF(M17>=5,"Medium","Low"))) -> Low | O17: Possible: laptops leave the office every day. Negligible: encryption and remote wipe limit the loss to the cost of the hardware. | P17: Tolerate | Q17: Accept. Write the remote working policy so the existing controls are documented (GAP-024). Monitor through the incident log. | R17: A.6.7, A.7.9, A.8.1 | S17: GAP-024 | T17: 3 | U17: 1 | V17: =T17*U17 -> 3 | W17: =IF(V17>=20,"Critical",IF(V17>=10,"High",IF(V17>=5,"Medium","Low"))) -> Low | X17: =INDEX(Methodology!$D$43:$D$46,MATCH(C17,Methodology!$A$43:$A$46,0)) -> 9 | Y17: =IF(M17<=X17,"Yes","No") -> Yes | Z17: =IF(V17<=X17,"Yes","No") -> Yes | AA17: 46477 | AB17: Accepted | AC17: 46322 | AD17: =AC17+IF(OR(N17="Critical",N17="High"),30,91) -> 46413 | AE17: Accepted by the Technical Director as risk owner. Shown to demonstrate that existing controls can already bring a risk within appetite.
A18: R-017 | B18: Unauthorised physical access to the legacy on premises host | C18: Operational Resilience | D18: The Hyper-V host sits in an unlocked communications cupboard that the building's cleaning contractors can reach. Someone could tamper with, remove or damage it, affecting two client workloads. | E18: Legacy Hyper-V host; two client workloads | F18: Unauthorised person; accidental damage | G18: Unlocked cupboard; no access log; no CCTV; no environmental monitoring | H18: C, I, A | I18: Infrastructure Lead | J18: Serviced building has a staffed reception and floor access control | K18: 2 | L18: 3 | M18: =K18*L18 -> 6 | N18: =IF(M18>=20,"Critical",IF(M18>=10,"High",IF(M18>=5,"Medium","Low"))) -> Medium | O18: Unlikely: building access control limits who can reach the cupboard. Moderate: only two clients are affected. | P18: Terminate | Q18: Migrate the two workloads to Azure and decommission the host. Until then, fit a locking rack and keep an access log. | R18: A.7.1, A.7.2, A.7.4, A.7.8 | S18: GAP-026 | T18: 1 | U18: 1 | V18: =T18*U18 -> 1 | W18: =IF(V18>=20,"Critical",IF(V18>=10,"High",IF(V18>=5,"Medium","Low"))) -> Low | X18: =INDEX(Methodology!$D$43:$D$46,MATCH(C18,Methodology!$A$43:$A$46,0)) -> 9 | Y18: =IF(M18<=X18,"Yes","No") -> Yes | Z18: =IF(V18<=X18,"Yes","No") -> Yes | AA18: 46626 | AB18: Open: treatment planned | AC18: 46322 | AD18: =AC18+IF(OR(N18="Critical",N18="High"),30,91) -> 46413 | AE18: Removing the host removes the risk and several physical controls from scope, which is cheaper than securing the cupboard.
A19: R-018 | B19: Prolonged loss of ability to deliver services | C19: Operational Resilience | D19: Loss of the Birmingham office, a long outage at a critical SaaS supplier or an Azure regional outage stops Lantern delivering services. With no business impact analysis and no tested plan, recovery is slow and SLAs are breached for every client. | E19: Service desk; critical SaaS platforms; Azure workloads | F19: Infrastructure failure; supplier outage; loss of site | G19: One page continuity plan from 2018; no BIA; no RTO or RPO; never tested | H19: A | I19: Operations Director | J19: Most systems are SaaS and reachable remotely; staff can work from home | K19: 2 | L19: 4 | M19: =K19*L19 -> 8 | N19: =IF(M19>=20,"Critical",IF(M19>=10,"High",IF(M19>=5,"Medium","Low"))) -> Medium | O19: Unlikely: SaaS and remote working give a good level of natural resilience. Major: a long outage would breach SLAs for all 140 clients. | P19: Treat | Q19: Carry out a business impact analysis. Set RTO and RPO per service. Rewrite the continuity plan. Test it every year. | R19: A.5.29, A.5.30 | S19: GAP-018 | T19: 2 | U19: 2 | V19: =T19*U19 -> 4 | W19: =IF(V19>=20,"Critical",IF(V19>=10,"High",IF(V19>=5,"Medium","Low"))) -> Low | X19: =INDEX(Methodology!$D$43:$D$46,MATCH(C19,Methodology!$A$43:$A$46,0)) -> 9 | Y19: =IF(M19<=X19,"Yes","No") -> Yes | Z19: =IF(V19<=X19,"Yes","No") -> Yes | AA19: 46568 | AB19: Open: treatment planned | AC19: 46322 | AD19: =AC19+IF(OR(N19="Critical",N19="High"),30,91) -> 46413
A20: R-019 | B20: Unauthorised access to the office network | C20: Operational Resilience | D20: The office Wi-Fi uses one shared key that has not changed since 2023 and is known to former staff. Anyone with the key can join the same flat network as corporate laptops and lab equipment. | E20: Office network; corporate laptops; legacy host | F20: Former employee; visitor; nearby attacker | G20: Shared key not rotated; no segregation; no guest network | H20: C, I | I20: Infrastructure Lead | J20: Defender firewall on managed laptops; building access control | K20: 3 | L20: 3 | M20: =K20*L20 -> 9 | N20: =IF(M20>=20,"Critical",IF(M20>=10,"High",IF(M20>=5,"Medium","Low"))) -> Medium | O20: Possible: people who no longer work at Lantern know the key. Moderate: gives a foothold rather than direct access to client platforms. | P20: Treat | Q20: Rotate the key now. Move the corporate network to WPA2/3 Enterprise against Entra ID. Separate corporate, lab and guest VLANs. Provide a guest network with a rotating key. | R20: A.8.20, A.8.21, A.8.22 | S20: GAP-034 | T20: 1 | U20: 2 | V20: =T20*U20 -> 2 | W20: =IF(V20>=20,"Critical",IF(V20>=10,"High",IF(V20>=5,"Medium","Low"))) -> Low | X20: =INDEX(Methodology!$D$43:$D$46,MATCH(C20,Methodology!$A$43:$A$46,0)) -> 9 | Y20: =IF(M20<=X20,"Yes","No") -> Yes | Z20: =IF(V20<=X20,"Yes","No") -> Yes | AA20: 46535 | AB20: Open: treatment planned | AC20: 46322 | AD20: =AC20+IF(OR(N20="Critical",N20="High"),30,91) -> 46413
A21: R-020 | B21: Insider misuse by a member of staff who was not properly screened | C21: Client Trust & Privileged Access | D21: A member of staff with privileged client access, hired without adequate checks, misuses that access to take or sell client data, including health data held for healthcare clients. | E21: Client data; credential vault | F21: Malicious insider | G21: Screening limited to inconsistent reference checks; no security obligations in contracts; no DLP; no monitoring | H21: C | I21: Operations Director | J21: General confidentiality clause in employment contracts | K21: 2 | L21: 5 | M21: =K21*L21 -> 10 | N21: =IF(M21>=20,"Critical",IF(M21>=10,"High",IF(M21>=5,"Medium","Low"))) -> High | O21: Unlikely: insider cases are rare, but nothing would deter or detect one. Severe: privileged access to special category health data. | P21: Treat | Q21: Introduce a screening standard including a basic DBS check for privileged roles. Add a security schedule to contracts and cover security breaches in the disciplinary policy. DLP and monitoring are delivered under R-006 and R-010. | R21: A.6.1, A.6.2, A.6.4, A.8.12 | S21: GAP-022, GAP-023, GAP-037 | T21: 1 | U21: 5 | V21: =T21*U21 -> 5 | W21: =IF(V21>=20,"Critical",IF(V21>=10,"High",IF(V21>=5,"Medium","Low"))) -> Medium | X21: =INDEX(Methodology!$D$43:$D$46,MATCH(C21,Methodology!$A$43:$A$46,0)) -> 6 | Y21: =IF(M21<=X21,"Yes","No") -> No | Z21: =IF(V21<=X21,"Yes","No") -> Yes | AA21: 46660 | AB21: Open: treatment planned | AC21: 46322 | AD21: =AC21+IF(OR(N21="Critical",N21="High"),30,91) -> 46352
A22: R-021 | B22: Lantern cannot meet duties under the Cyber Security and Resilience Bill | C22: Regulatory & Legal | D22: The Bill is expected to bring managed service providers into scope, with 24 hour and 72 hour incident reporting and turnover based penalties. If Lantern is in scope and cannot meet these duties, it faces penalties and loses the trust of clients in regulated sectors. | E22: Regulatory standing; client relationships | F22: Regulatory enforcement | G22: No incident response capability; no regulatory register; nobody tracking the Bill's progress | H22: N/A | I22: Managing Director | J22: Legal advisers have flagged that Lantern is likely to be in scope | K22: 3 | L22: 4 | M22: =K22*L22 -> 12 | N22: =IF(M22>=20,"Critical",IF(M22>=10,"High",IF(M22>=5,"Medium","Low"))) -> High | O22: Possible: the Bill had not received Royal Assent at the time of assessment and the detailed thresholds are still to be set. Major: turnover based penalties and the reporting duty itself. | P22: Treat | Q22: Determine whether Lantern is in scope. Complete a readiness assessment (Artefact 04). Build the 24 hour reporting procedure into the incident response plan. Track the Bill in the legal and regulatory register. | R22: A.5.5, A.5.24, A.5.31 | S22: GAP-013, GAP-019 | T22: 2 | U22: 3 | V22: =T22*U22 -> 6 | W22: =IF(V22>=20,"Critical",IF(V22>=10,"High",IF(V22>=5,"Medium","Low"))) -> Medium | X22: =INDEX(Methodology!$D$43:$D$46,MATCH(C22,Methodology!$A$43:$A$46,0)) -> 6 | Y22: =IF(M22<=X22,"Yes","No") -> No | Z22: =IF(V22<=X22,"Yes","No") -> Yes | AA22: 46568 | AB22: Open: treatment planned | AC22: 46322 | AD22: =AC22+IF(OR(N22="Critical",N22="High"),30,91) -> 46352 | AE22: Reassess when the Bill receives Royal Assent and secondary legislation is published.

Sheet Treatment Plan
A1: Action ID | B1: Risk ID(s) | C1: Action | D1: Owner | E1: Roadmap phase | F1: Target date | G1: Status | H1: Gap refs | I1: Evidence of completion
A2: TP-01 | B2: R-001 | C2: Enforce phishing resistant MFA on the RMM platform as an emergency change | D2: Technical Director | E2: 0 | F2: 46332 | G2: Not started | H2: GAP-030 | I2: RMM security settings export showing MFA enforced for every user
A3: TP-02 | B3: R-001, R-009 | C3: Enforce MFA on the backup console | D3: Technical Director | E3: 0 | F3: 46332 | G3: Not started | H3: GAP-030 | I3: Console settings screenshot and user list
A4: TP-03 | B4: R-002 | C4: Reconcile every account on RMM, vault, backup console, PSA and Partner Center with the HR roster and disable orphaned accounts | D4: Technical Director | E4: 0 | F4: 46339 | G4: Not started | H4: GAP-021 | I4: Signed reconciliation record per platform
A5: TP-04 | B5: R-001, R-003 | C5: Replace shared credentials on six client tenancies with named accounts | D5: Infrastructure Lead | E5: 0 | F5: 46339 | G5: Not started | H5: GAP-016 | I5: Account list per tenancy showing named users only
A6: TP-05 | B6: R-019 | C6: Rotate the office Wi-Fi key | D6: Infrastructure Lead | E6: 0 | F6: 46332 | G6: Not started | H6: GAP-034 | I6: Change record in the PSA
A7: TP-06 | B7: R-012, R-013 | C7: Appoint an Information Security Manager with at least 0.4 FTE allocated | D7: Managing Director | E7: 1 | F7: 46374 | G7: Not started | H7: GAP-008 | I7: Signed role description and allocation
A8: TP-07 | B8: R-012 | C8: Approve ISMS scope, risk methodology and risk appetite | D8: Managing Director | E8: 1 | F8: 46416 | G8: Not started | H8: GAP-001, GAP-002 | I8: Leadership meeting minutes recording approval
A9: TP-08 | B9: R-012 | C9: Produce the full Statement of Applicability from this register | D9: Information Security Manager | E9: 1 | F9: 46444 | G9: Not started | H9: GAP-003 | I9: SoA version 1.0 approved
A10: TP-09 | B10: R-002 | C10: Introduce a leaver checklist naming every platform with a 4 hour revocation target and Technical Director sign off | D10: Operations Director | E10: 1 | F10: 46402 | G10: Not started | H10: GAP-021 | I10: Procedure plus the first three completed checklists
A11: TP-10 | B11: R-014 | C11: Subscribe to NCSC Early Warning and vendor advisories; add a weekly review to the technical meeting | D11: Infrastructure Lead | E11: 1 | F11: 46374 | G11: Not started | H11: GAP-017 | I11: Subscription confirmation and meeting notes
A12: TP-11 | B12: R-015 | C12: Introduce a caller verification procedure for password resets and access changes | D12: Operations Director | E12: 1 | F12: 46416 | G12: Not started | H12: GAP-011 | I12: Procedure and service desk briefing record
A13: TP-12 | B13: R-009 | C13: Write a backup policy, confirm immutability and restore test Lantern's own data | D13: Infrastructure Lead | E13: 1 | F13: 46416 | G13: Not started | H13: GAP-035 | I13: Policy, immutability setting evidence, restore test record
... A44: TP-43 | B44: R-008 | C44: Remove stored tenant administrator credentials from the vault after GDAP migration and deploy Windows LAPS to managed client devices | D44: Infrastructure Lead | E44: 3 | F44: 46598 | G44: Not started | H44: TPRA-001 (TPR-09) | I44: Vault inventory showing no tenant admin credentials; LAPS coverage report
A46: Roadmap phases match the gap assessment: 0 Immediate, 1 Foundation, 2 Core controls, 3 Supporting controls, 4 Operate and audit. Status is the only column expected to change week to week.

Sheet Change Log
A1: Version | B1: Date | C1: Author | D1: Change | E1: Approved by
A2: 1.0 | B2: 46322 | C2: Eugene Hayford | D2: First issue. 21 risks identified from the October 2026 gap assessment. Methodology and appetite proposed for approval. | E2: Pending (Managing Director)
A3: 1.1 | B3: 46324 | C3: Eugene Hayford | D3: R-008 updated after third party assessment TPRA-001: target impact reduced from 5 to 3 by removing tenant admin credentials from the vault, bringing the target within appetite. Actions TP-41 to TP-43 added. | E3: Pending (Managing Director)
