Workbook

Sheet Cover
A1: Statement of Applicability
A2: Lantern Managed Services Ltd, ISO/IEC 27001:2022 Annex A
A4: Prepared by | B4: Eugene Hayford
A5: Document reference | B5: LMS-ISMS-SOA-001
A6: Version | B6: 1.0
A7: Date | B7: October 2026
A8: Classification | B8: Confidential, Lantern internal
A9: Standard | B9: ISO/IEC 27001:2022 Clause 6.1.3 d); control guidance from ISO/IEC 27002:2022
A10: ISMS scope | B10: Managed IT support, managed cloud, managed backup and IT project services delivered from Birmingham, Manchester and remote locations, including Lantern's administrative access to client environments.
A11: Source documents | B11: Risk Register LMS-ISMS-RR-001 v1.2 (risk links and treatment actions TP-01 to TP-46); ISO/IEC 27001:2022 Gap Assessment (findings GAP-001 to GAP-040)
A12: Approval status | B12: Draft for approval by the Managing Director
A14: Scenario notice
A15: Lantern Managed Services Ltd is a fictional organisation used to demonstrate ISO/IEC 27001 practice. No real client, employee or commercial information is used.
A17: How this SoA was built
A18: 1. Each risk in the register was mapped to the Annex A controls that treat it. 56 controls are selected this way and their risk IDs appear in the Linked risks column.
A19: 2. Every remaining control was then tested against legal and regulatory requirements, client contracts and questionnaires, and business need. A control was only excluded if the activity it covers does not happen inside the ISMS scope.
A20: 3. Implementation status and maturity come from the gap assessment, scored per control. Five controls had no gap finding but were found weak during this review and are marked as added at SoA review.
A21: 4. Every applicable control that is not yet implemented is tied to a treatment action (TP reference) or a gap assessment roadmap phase, with an owner and a target date.
A23: Reason for inclusion codes
A24: RA | B24: Risk assessment: selected to treat one or more risks in the register
A25: LR | B25: Legal or regulatory requirement (UK GDPR, DPA 2018, PECR, NIS Regulations, expected CSR Bill duties)
A26: CO | B26: Contractual obligation or client expectation, including tender and security questionnaire requirements
A27: BR | B27: Business requirement or recognised good practice needed for the ISMS to operate
A29: Implementation status
A30: Implemented | B30: All elements of the control are in place, documented and producing records (maturity 3 or above).
A31: Partially implemented | B31: Some elements operate, usually technical, but the control is incomplete or undocumented.
A32: Not implemented | B32: The control is absent or exists only as informal individual practice.
A33: Excluded | B33: Not applicable to the ISMS scope, with the justification recorded.
A35: Maturity uses the 0 to 5 scale defined in the gap assessment (0 Absent, 1 Initial, 2 Developing, 3 Defined, 4 Managed, 5 Optimising). Status and maturity are recorded separately because a control can be partly in place technically while still scoring 1 for governance.

Sheet Summary
A1: SoA Summary
A2: All figures calculate from the SoA sheet
A4: Applicability and implementation by theme
A5: Theme | B5: Controls | C5: Applicable | D5: Excluded | E5: Implemented | F5: Partially implemented | G5: Not implemented | H5: Avg maturity | I5: At maturity 3+
A6: A.5 Organizational | B6: =COUNTIF(SoA!$B$2:$B$94,A6) -> 37 | C6: =COUNTIFS(SoA!$B$2:$B$94,A6,SoA!$D$2:$D$94,"Yes") -> 37 | D6: =COUNTIFS(SoA!$B$2:$B$94,A6,SoA!$D$2:$D$94,"No") -> 0 | E6: =COUNTIFS(SoA!$B$2:$B$94,A6,SoA!$I$2:$I$94,"Implemented") -> 4 | F6: =COUNTIFS(SoA!$B$2:$B$94,A6,SoA!$I$2:$I$94,"Partially implemented") -> 16 | G6: =COUNTIFS(SoA!$B$2:$B$94,A6,SoA!$I$2:$I$94,"Not implemented") -> 17 | H6: =AVERAGEIFS(SoA!$H$2:$H$94,SoA!$B$2:$B$94,A6,SoA!$D$2:$D$94,"Yes") -> 1.0810811 | I6: =COUNTIFS(SoA!$B$2:$B$94,A6,SoA!$H$2:$H$94,">=3") -> 4
A7: A.6 People | B7: =COUNTIF(SoA!$B$2:$B$94,A7) -> 8 | C7: =COUNTIFS(SoA!$B$2:$B$94,A7,SoA!$D$2:$D$94,"Yes") -> 8 | D7: =COUNTIFS(SoA!$B$2:$B$94,A7,SoA!$D$2:$D$94,"No") -> 0 | E7: =COUNTIFS(SoA!$B$2:$B$94,A7,SoA!$I$2:$I$94,"Implemented") -> 0 | F7: =COUNTIFS(SoA!$B$2:$B$94,A7,SoA!$I$2:$I$94,"Partially implemented") -> 6 | G7: =COUNTIFS(SoA!$B$2:$B$94,A7,SoA!$I$2:$I$94,"Not implemented") -> 2 | H7: =AVERAGEIFS(SoA!$H$2:$H$94,SoA!$B$2:$B$94,A7,SoA!$D$2:$D$94,"Yes") -> 1.375 | I7: =COUNTIFS(SoA!$B$2:$B$94,A7,SoA!$H$2:$H$94,">=3") -> 0
A8: A.7 Physical | B8: =COUNTIF(SoA!$B$2:$B$94,A8) -> 14 | C8: =COUNTIFS(SoA!$B$2:$B$94,A8,SoA!$D$2:$D$94,"Yes") -> 14 | D8: =COUNTIFS(SoA!$B$2:$B$94,A8,SoA!$D$2:$D$94,"No") -> 0 | E8: =COUNTIFS(SoA!$B$2:$B$94,A8,SoA!$I$2:$I$94,"Implemented") -> 6 | F8: =COUNTIFS(SoA!$B$2:$B$94,A8,SoA!$I$2:$I$94,"Partially implemented") -> 6 | G8: =COUNTIFS(SoA!$B$2:$B$94,A8,SoA!$I$2:$I$94,"Not implemented") -> 2 | H8: =AVERAGEIFS(SoA!$H$2:$H$94,SoA!$B$2:$B$94,A8,SoA!$D$2:$D$94,"Yes") -> 2.0714286 | I8: =COUNTIFS(SoA!$B$2:$B$94,A8,SoA!$H$2:$H$94,">=3") -> 6
A9: A.8 Technological | B9: =COUNTIF(SoA!$B$2:$B$94,A9) -> 34 | C9: =COUNTIFS(SoA!$B$2:$B$94,A9,SoA!$D$2:$D$94,"Yes") -> 33 | D9: =COUNTIFS(SoA!$B$2:$B$94,A9,SoA!$D$2:$D$94,"No") -> 1 | E9: =COUNTIFS(SoA!$B$2:$B$94,A9,SoA!$I$2:$I$94,"Implemented") -> 8 | F9: =COUNTIFS(SoA!$B$2:$B$94,A9,SoA!$I$2:$I$94,"Partially implemented") -> 11 | G9: =COUNTIFS(SoA!$B$2:$B$94,A9,SoA!$I$2:$I$94,"Not implemented") -> 14 | H9: =AVERAGEIFS(SoA!$H$2:$H$94,SoA!$B$2:$B$94,A9,SoA!$D$2:$D$94,"Yes") -> 1.6969697 | I9: =COUNTIFS(SoA!$B$2:$B$94,A9,SoA!$H$2:$H$94,">=3") -> 8
A10: Total | B10: =SUM(B6:B9) -> 93 | C10: =SUM(C6:C9) -> 92 | D10: =SUM(D6:D9) -> 1 | E10: =SUM(E6:E9) -> 18 | F10: =SUM(F6:F9) -> 39 | G10: =SUM(G6:G9) -> 35 | H10: =AVERAGEIF(SoA!$D$2:$D$94,"Yes",SoA!$H$2:$H$94) -> 1.4782609 | I10: =SUM(I6:I9) -> 18
A11: Check: implemented + partial + not implemented + excluded = 93 | E11: =IF(E10+F10+G10+D10=B10,"OK","Check rows") -> OK
A13: Why controls are included
A14: Reason | B14: Controls citing it | C14: % of applicable
A15: RA Risk assessment | B15: =COUNTIF(SoA!$E$2:$E$94,"*RA*") -> 56 | C15: =B15/C$10 -> 0.60869565
A16: LR Legal or regulatory | B16: =COUNTIF(SoA!$E$2:$E$94,"*LR*") -> 17 | C16: =B16/C$10 -> 0.18478261
A17: CO Contractual | B17: =COUNTIF(SoA!$E$2:$E$94,"*CO*") -> 25 | C17: =B17/C$10 -> 0.27173913
A18: BR Business requirement | B18: =COUNTIF(SoA!$E$2:$E$94,"*BR*") -> 56 | C18: =B18/C$10 -> 0.60869565
A19: A control can have more than one reason, so the counts add up to more than the number of applicable controls.
A21: Traceability
A22: Controls linked to at least one register risk | F22: =COUNTIF(SoA!$G$2:$G$94,"R-*") -> 56
A23: Applicable controls with no linked risk (justified on LR, CO or BR) | F23: =COUNTIFS(SoA!$D$2:$D$94,"Yes",SoA!$G$2:$G$94,"None") -> 36
A24: Controls with a gap assessment finding | F24: =COUNTIF(SoA!$K$2:$K$94,"GAP-*") -> 69
A25: Weak controls added at SoA review (no prior finding) | F25: =COUNTIF(SoA!$K$2:$K$94,"Not raised*") -> 5
A26: Applicable controls not yet implemented | F26: =F10+G10 -> 74
A27: of which have a treatment action (TP) assigned | F27: =COUNTIFS(SoA!$I$2:$I$94,"<>Implemented",SoA!$D$2:$D$94,"Yes",SoA!$L$2:$L$94,"TP-*") -> 50
A28: of which are delivered through a roadmap phase | F28: =COUNTIFS(SoA!$I$2:$I$94,"<>Implemented",SoA!$D$2:$D$94,"Yes",SoA!$L$2:$L$94,"Roadmap*") -> 24
A30: Exclusions
A31: Control | B31: Title | E31: Justification
A32: A.8.30 | B32: Outsourced development | E32: Lantern does not commission software or script development from third parties. All automation is written in house by employees. Re-assess if any development is outsourced.
A34: One exclusion out of 93 is deliberate. The 2022 control set applies to almost every organisation, and an auditor will test each exclusion against the scope. Controls that are hard or not yet in place stay applicable; only controls whose activity does not happen inside the scope are excluded. A.8.25 to A.8.29 and A.8.31 to A.8.33 were kept in because engineers write and run scripts across client estates, which is development activity even though Lantern sells no software.

Sheet SoA
A1: Control | B1: Theme | C1: Control title | D1: Applicable | E1: Reason for inclusion | F1: Justification | G1: Linked risks | H1: Current maturity (0-5) | I1: Implementation status | J1: Current implementation | K1: Gap assessment ref | L1: Delivered by | M1: Control owner | N1: Target date
A2: A.5.1 | B2: A.5 Organizational | C2: Policies for information security | D2: Yes | E2: RA, BR, CO | F2: Foundation of the ISMS. Tender and client questionnaires ask for an approved, current policy set. | G2: R-012 | H2: 1 | I2: Partially implemented | J2: A 2019 policy exists but has never been reviewed or communicated to staff. | K2: GAP-007 | L2: Roadmap Phase 1 | M2: Managing Director | N2: 46444
A3: A.5.2 | B3: A.5 Organizational | C3: Information security roles and responsibilities | D3: Yes | E3: RA, BR | F3: Security work falls to one person with no mandate. Roles must be defined for the ISMS to run. | G3: R-012, R-013 | H3: 1 | I3: Not implemented | J3: No roles defined. The Technical Director covers security informally. | K3: GAP-008 | L3: TP-06 | M3: Managing Director | N3: 46374
A4: A.5.3 | B4: A.5 Organizational | C4: Segregation of duties | D4: Yes | E4: RA, BR | F4: Engineers can request, approve and run changes on client estates on their own. | G4: R-013 | H4: 1 | I4: Partially implemented | J4: Finance approvals are separated from requesters. No separation in engineering changes or access approvals. | K4: GAP-031 | L4: TP-17 | M4: Technical Director | N4: 46477
A5: A.5.4 | B5: A.5 Organizational | C5: Management responsibilities | D5: Yes | E5: BR | F5: Leadership has to require staff to follow security policy. Today security is only discussed after incidents. | G5: None | H5: 1 | I5: Not implemented | J5: No expectations set or communicated by management. | K5: GAP-005, GAP-007 | L5: Roadmap Phase 1 | M5: Managing Director | N5: 46444
A6: A.5.5 | B6: A.5 Organizational | C6: Contact with authorities | D6: Yes | E6: RA, LR | F6: Lantern must be able to notify the ICO, and its CSR Bill regulator once designated, and report crime to Action Fraud. | G6: R-021 | H6: 2 | I6: Partially implemented | J6: Registered with the ICO. No documented contacts or reporting routes. | K6: GAP-013 | L6: TP-26 | M6: Technical Director | N6: 46477
A7: A.5.6 | B7: A.5 Organizational | C7: Contact with special interest groups | D7: Yes | E7: BR | F7: MSP threat sharing groups give early warning of attacks on RMM and backup tooling. | G7: None | H7: 2 | I7: Partially implemented | J7: Engineers take part in vendor user communities on their own initiative. | K7: GAP-017 | L7: TP-10 | M7: Infrastructure Lead | N7: 46374
A8: A.5.7 | B8: A.5 Organizational | C8: Threat intelligence | D8: Yes | E8: RA, BR | F8: MSP targeting is an active threat pattern; awareness of RMM platform specific threats is needed to act in time. | G8: R-014 | H8: 1 | I8: Not implemented | J8: Individual engineers read security news informally. Nothing is recorded or acted on. | K8: GAP-017 | L8: TP-10 | M8: Infrastructure Lead | N8: 46374
A9: A.5.8 | B9: A.5 Organizational | C9: Information security in project management | D9: Yes | E9: CO | F9: Project services deliver migrations and infrastructure changes inside client environments. | G9: None | H9: 1 | I9: Not implemented | J9: The project method has no security checkpoint or sign off. | K9: Not raised separately; added at SoA review | L9: Roadmap Phase 3 | M9: Operations Director | N9: 46660
A10: A.5.9 | B10: A.5 Organizational | C10: Inventory of information and other associated assets | D10: Yes | E10: BR | F10: Lantern cannot protect what it has not identified, and every asset needs an owner. | G10: None | H10: 1 | I10: Partially implemented | J10: Laptops are inventoried in Intune. There is no information asset register. | K10: GAP-014 | L10: Roadmap Phase 1 | M10: Technical Director | N10: 46444
A11: A.5.10 | B11: A.5 Organizational | C11: Acceptable use of information and other associated assets | D11: Yes | E11: BR | F11: Staff handle client data and credentials every day with no written rules. | G11: None | H11: 1 | I11: Not implemented | J11: No acceptable use policy. | K11: GAP-014 | L11: Roadmap Phase 1 | M11: Operations Director | N11: 46444
A12: A.5.11 | B12: A.5 Organizational | C12: Return of assets | D12: Yes | E12: BR | F12: Leavers hold laptops and may hold client documentation. | G12: None | H12: 3 | I12: Implemented | J12: HR leaver form requires laptop return. Device is wiped through Intune and the asset record updated. | K12: No finding | L12: Maintain; verify at internal audit | M12: Operations Director | N12: Ongoing
A13: A.5.12 | B13: A.5 Organizational | C13: Classification of information | D13: Yes | E13: RA, BR | F13: Client credentials, health data and marketing material are currently handled the same way. | G13: R-006 | H13: 0 | I13: Not implemented | J13: No classification scheme. | K13: GAP-015 | L13: TP-34 | M13: Technical Director | N13: 46568
A14: A.5.13 | B14: A.5 Organizational | C14: Labelling of information | D14: Yes | E14: RA, BR | F14: Labels are how staff and DLP rules recognise classified information. | G14: R-006 | H14: 0 | I14: Not implemented | J14: No labelling. | K14: GAP-015 | L14: TP-34 | M14: Technical Director | N14: 46568
A15: A.5.14 | B15: A.5 Organizational | C15: Information transfer | D15: Yes | E15: LR, CO | F15: Client data and credentials are exchanged with clients and suppliers every day. | G15: None | H15: 3 | I15: Implemented | J15: TLS enforced on Microsoft 365 mail. External sharing limited to named guests. Credentials shared only through the vault. | K15: No finding | L15: Maintain; verify at internal audit | M15: Technical Director | N15: Ongoing
A16: A.5.15 | B16: A.5 Organizational | C16: Access control | D16: Yes | E16: RA, CO | F16: Privileged access to 140 client environments is the organisation's principal risk. | G16: R-001, R-003 | H16: 1 | I16: Partially implemented | J16: Access granted at engineer discretion. 99 clients on granular delegated admin. No policy. | K16: GAP-016 | L16: TP-14 | M16: Technical Director | N16: 46477
A17: A.5.16 | B17: A.5 Organizational | C17: Identity management | D17: Yes | E17: RA, BR | F17: Every action on a client system must be traceable to one person. | G17: R-002, R-003 | H17: 2 | I17: Partially implemented | J17: Named Entra ID identities for staff. Shared accounts on six client tenancies and 9 shared or service accounts internally. | K17: GAP-016 | L17: TP-04 | M17: Infrastructure Lead | N17: 46339
A18: A.5.17 | B18: A.5 Organizational | C18: Authentication information | D18: Yes | E18: RA, CO | F18: The credential vault holds client administrative credentials. | G18: R-001 | H18: 1 | I18: Partially implemented | J18: Password manager and vault in use. No MFA on RMM or backup console. No custody rules for vault recovery keys. | K18: GAP-030, GAP-036 | L18: TP-01 | M18: Technical Director | N18: 46332
A19: A.5.18 | B19: A.5 Organizational | C19: Access rights | D19: Yes | E19: RA, BR | F19: Leaver accounts were found active three months after the engineers left. | G19: R-002, R-003 | H19: 1 | I19: Partially implemented | J19: Entra ID accounts disabled on leaving, but client platforms are missed. No access reviews. | K19: GAP-021, GAP-016 | L19: TP-13 | M19: Technical Director | N19: 46477
A20: A.5.19 | B20: A.5 Organizational | C20: Information security in supplier relationships | D20: Yes | E20: RA, CO | F20: Four critical SaaS suppliers hold or can reach client data. | G20: R-008 | H20: 0 | I20: Not implemented | J20: Finance holds a payment list only. | K20: GAP-012 | L20: TP-23 | M20: Finance Director | N20: 46477
A21: A.5.20 | B21: A.5 Organizational | C21: Addressing information security within supplier agreements | D21: Yes | E21: RA, LR, CO | F21: UK GDPR requires processor terms with sub-processors, and clients expect security terms to flow down. | G21: R-008 | H21: 0 | I21: Not implemented | J21: Standard vendor terms accepted with no security schedule. | K21: GAP-012 | L21: Roadmap Phase 2 | M21: Finance Director | N21: 46568
A22: A.5.21 | B22: A.5 Organizational | C22: Managing information security in the ICT supply chain | D22: Yes | E22: RA, CO | F22: RMM agents and backup software run on every client endpoint. | G22: R-008 | H22: 0 | I22: Not implemented | J22: No assessment of how vendors build, sign or release updates. | K22: GAP-012 | L22: TP-24 | M22: Technical Director | N22: 46535
A23: A.5.22 | B23: A.5 Organizational | C23: Monitoring, review and change management of supplier services | D23: Yes | E23: RA, CO | F23: Supplier changes and incidents directly affect client service. | G23: R-008 | H23: 0 | I23: Not implemented | J23: Suppliers are never reviewed. | K23: GAP-012 | L23: Roadmap Phase 2 | M23: Finance Director | N23: 46568
A24: A.5.23 | B24: A.5 Organizational | C24: Information security for use of cloud services | D24: Yes | E24: RA, BR | F24: All critical tooling is SaaS and leaving any of it would be operationally severe. | G24: R-008 | H24: 1 | I24: Partially implemented | J24: Cloud services bought without security review. No exit plans. | K24: GAP-020 | L24: TP-32 | M24: Technical Director | N24: 46598
A25: A.5.24 | B25: A.5 Organizational | C25: Information security incident management planning and preparation | D25: Yes | E25: RA, LR | F25: Required for UK GDPR breach notification and the reporting duty expected under the CSR Bill. | G25: R-011, R-021 | H25: 1 | I25: Not implemented | J25: No plan. Incidents handled as ordinary service desk tickets. | K25: GAP-013 | L25: TP-26 | M25: Technical Director | N25: 46477
A26: A.5.25 | B26: A.5 Organizational | C26: Assessment and decision on information security events | D26: Yes | E26: RA, LR | F26: Lantern must be able to recognise a reportable incident within hours. | G26: R-011 | H26: 1 | I26: Not implemented | J26: No classification or severity model. | K26: GAP-013 | L26: TP-27 | M26: Operations Director | N26: 46477
A27: A.5.26 | B27: A.5 Organizational | C27: Response to information security incidents | D27: Yes | E27: RA, CO | F27: Clients contract for Lantern's support during incidents. | G27: R-011 | H27: 1 | I27: Partially implemented | J27: Engineers respond capably but without defined roles or escalation. | K27: GAP-013 | L27: TP-28 | M27: Technical Director | N27: 46535
... A32: A.5.31 | B32: A.5 Organizational | C32: Legal, statutory, regulatory and contractual requirements | D32: Yes | E32: RA, LR | F32: UK GDPR, DPA 2018, PECR and the NIS Regulations apply, and the CSR Bill is expected to. | G32: R-007, R-021 | H32: 1 | I32: Not implemented | J32: No legal and regulatory register. | K32: GAP-019 | L32: TP-22 | M32: Finance Director | N32: 46477
A33: A.5.32 | B33: A.5 Organizational | C33: Intellectual property rights | D33: Yes | E33: LR | F33: Lantern resells and deploys licensed software into client environments. | G33: None | H33: 3 | I33: Implemented | J33: Licences managed through Partner Center and the distributor portal, reconciled quarterly by Finance. | K33: No finding | L33: Maintain; verify at internal audit | M33: Finance Director | N33: Ongoing
A34: A.5.33 | B34: A.5 Organizational | C34: Protection of records | D34: Yes | E34: LR | F34: Financial and HR records must be kept for statutory periods. | G34: None | H34: 3 | I34: Implemented | J34: Microsoft 365 retention policies applied to finance and HR libraries. | K34: No finding | L34: Maintain; verify at internal audit | M34: Finance Director | N34: Ongoing
A35: A.5.34 | B35: A.5 Organizational | C35: Privacy and protection of PII | D35: Yes | E35: RA, LR, CO | F35: Lantern processes client personal data, including health data, as a processor. | G35: R-006, R-007 | H35: 1 | I35: Partially implemented | J35: Article 28 terms in 118 of 140 contracts. No Article 30 records. | K35: GAP-019 | L35: TP-21 | M35: Finance Director | N35: 46507
A36: A.5.35 | B36: A.5 Organizational | C36: Independent review of information security | D36: Yes | E36: RA, BR | F36: Certification needs independent review and Lantern has none beyond Cyber Essentials. | G36: R-012 | H36: 1 | I36: Partially implemented | J36: Annual Cyber Essentials (basic) certification only. | K36: GAP-004 | L36: TP-40 | M36: Managing Director | N36: 46717
A37: A.5.36 | B37: A.5 Organizational | C37: Compliance with policies, rules and standards for information security | D37: Yes | E37: BR | F37: Policies only reduce risk if someone checks they are followed. | G37: None | H37: 0 | I37: Not implemented | J37: No compliance checks. | K37: GAP-004 | L37: TP-40 | M37: Information Security Manager | N37: 46717
A38: A.5.37 | B38: A.5 Organizational | C38: Documented operating procedures | D38: Yes | E38: BR | F38: Keeps service consistent across 19 service desk staff and 11 engineers. | G38: None | H38: 2 | I38: Partially implemented | J38: Runbooks held in the documentation platform, with several uncontrolled versions. | K38: GAP-010 | L38: Roadmap Phase 1 | M38: Operations Director | N38: 46444
A39: A.6.1 | B39: A.6 People | C39: Screening | D39: Yes | E39: RA, LR, CO | F39: Engineers get privileged access to clients holding special category data. | G39: R-020 | H39: 1 | I39: Partially implemented | J39: Right to work checked. Reference checks inconsistent. No other checks. | K39: GAP-022 | L39: TP-30 | M39: Operations Director | N39: 46477
A40: A.6.2 | B40: A.6 People | C40: Terms and conditions of employment | D40: Yes | E40: RA, BR | F40: Security obligations have to be in the contract to be enforceable. | G40: R-020 | H40: 2 | I40: Partially implemented | J40: General confidentiality clause only. | K40: GAP-023 | L40: Roadmap Phase 2 | M40: Operations Director | N40: 46568
A41: A.6.3 | B41: A.6 People | C41: Information security awareness, education and training | D41: Yes | E41: RA, CO | F41: Clients and insurers expect regular training, and phishing is a top risk. | G41: R-015 | H41: 1 | I41: Partially implemented | J41: Annual phishing test with 61% completion. | K41: GAP-011 | L41: TP-38 | M41: Operations Director | N41: 46568
A42: A.6.4 | B42: A.6 People | C42: Disciplinary process | D42: Yes | E42: RA, BR | F42: Staff need to know the consequence of breaching security policy. | G42: R-020 | H42: 1 | I42: Not implemented | J42: Disciplinary policy does not mention security. | K42: GAP-023 | L42: Roadmap Phase 2 | M42: Operations Director | N42: 46568
A43: A.6.5 | B43: A.6 People | C43: Responsibilities after termination or change of employment | D43: Yes | E43: RA, CO | F43: Demonstrated control failure with privileged access retained after employment ended. | G43: R-002 | H43: 1 | I43: Partially implemented | J43: Entra ID disabled on leaving. Client platforms not covered. No verification. | K43: GAP-021 | L43: TP-09 | M43: Operations Director | N43: 46402
A44: A.6.6 | B44: A.6 People | C44: Confidentiality or non-disclosure agreements | D44: Yes | E44: CO | F44: Contractors and project staff see client information. | G44: None | H44: 2 | I44: Partially implemented | J44: Employees covered by contract clause. Contractor NDAs inconsistent. | K44: GAP-023 | L44: Roadmap Phase 2 | M44: Operations Director | N44: 46568
...

Sheet Change Log
A1: Version | B1: Date | C1: Author | D1: Change | E1: Approved by
A2: 1.0 | B2: 46324 | C2: Eugene Hayford | D2: First issue. All 93 Annex A controls assessed. 92 applicable, 1 excluded (A.8.30). Applicability derived from Risk Register v1.2. | E2: Pending (Managing Director)
